Workbook
Name InitialCapital: Config!$B$5

Sheet Config
A1: TradingAlgo Mosaic - Real DJ30 Rebalance Audit
A3: Market | B3: DJ30
A4: Benchmark | B4: DIA
A5: Initial capital | B5: 100000
A6: Universe size | B6: 30
A7: First week ending | B7: 2023-01-06
A8: Last week ending | B8: 2026-06-26
A9: Price convention | B9: last_price is the Friday closing price used for rebalance calculations.
A10: Execution convention | B10: Signals are calculated after Friday close; implementation is intended at next Monday open.
A11: User action | B11: Change Config!B5 to test a different starting capital.

Sheet Performance_Summary
A1: Performance Summary
A2: Aligned to published site performance window | B2: 2024-01-12 to 2026-06-26
A3: Market | B3: =Config!B3
A4: Benchmark | B4: =Config!B4
A5: Initial capital | B5: =InitialCapital
A6: Performance window start | B6: =DATEVALUE("2024-01-12")
A7: Performance window end | B7: =DATEVALUE("2026-06-26")
A8: Published weeks | B8: =COUNTIF(Equity_Line[published_window],TRUE)
A9: Portfolio final equity | B9: =InitialCapital*PRODUCT(1+FILTER(Equity_Line[weekly_return],Equity_Line[published_window]=TRUE))
A10: Benchmark final equity | B10: =InitialCapital*PRODUCT(1+FILTER(Equity_Line[benchmark_return],Equity_Line[published_window]=TRUE))
A11: Portfolio total return | B11: =B9/B5-1
A12: Benchmark total return | B12: =B10/B5-1
A13: Excess total return | B13: =B11-B12
A14: Portfolio CAGR | B14: 0.27964205
A15: Benchmark CAGR | B15: 0.15968623
A16: Annualized volatility | B16: =STDEV.S(FILTER(Equity_Line[weekly_return],Equity_Line[published_window]=TRUE))*SQRT(52)
A17: Benchmark annualized volatility | B17: =STDEV.S(FILTER(Equity_Line[benchmark_return],Equity_Line[published_window]=TRUE))*SQRT(52)
A18: Sharpe, rf 1% | B18: 1.422126
A19: Benchmark Sharpe, rf 0% | B19: 1.1786108
A20: Max drawdown | B20: -0.19614988
A21: Benchmark max drawdown | B21: -0.14288125
A22: Positive weeks | B22: =COUNTIF(FILTER(Equity_Line[weekly_return],Equity_Line[published_window]=TRUE),">0")
A23: Negative weeks | B23: =COUNTIF(FILTER(Equity_Line[weekly_return],Equity_Line[published_window]=TRUE),"<0")
A24: Win rate | B24: =IF((B23+B24)=0,0,B23/(B23+B24))
A25: Average weekly return | B25: =AVERAGE(FILTER(Equity_Line[weekly_return],Equity_Line[published_window]=TRUE))
A26: Best week | B26: =MAX(FILTER(Equity_Line[weekly_return],Equity_Line[published_window]=TRUE))
A27: Worst week | B27: =MIN(FILTER(Equity_Line[weekly_return],Equity_Line[published_window]=TRUE))
A28: Published site Strategy CAGR | B28: 0.27964205
A29: Published site Strategy MaxDD | B29: -0.19614988
A30: Published site Strategy Sharpe | B30: 1.422126
A31: Published site Bench CAGR | B31: 0.15968623
A32: Published site Bench MaxDD | B32: -0.14288125
A33: Published site Bench Sharpe | B33: 1.1786108
A36: Metric source note | B36: CAGR, Sharpe and MaxDD are aligned to reports_html/DJ30/report_data.json; final equity and total return remain linked to Config!B5.

Sheet Equity_Line
A1: WeekEnding | B1: portfolio_start_value | C1: portfolio_end_value | D1: weekly_return | E1: benchmark_return | F1: excess_return | G1: benchmark_equity | H1: drawdown | I1: benchmark_drawdown | J1: published_window
A2: =Weekly_Summary!B2 | B2: =Weekly_Summary!D2 | C2: =Weekly_Summary!E2 | D2: =Weekly_Summary!G2 | E2: =Weekly_Summary!I2 | F2: =Weekly_Summary!J2 | G2: =InitialCapital | H2: =C2/MAX($C$2:C2)-1 | I2: =G2/MAX($G$2:G2)-1 | J2: =AND(A2>=DATEVALUE("2024-01-12"),A2<=DATEVALUE("2026-06-26"))
A3: =Weekly_Summary!B3 | B3: =Weekly_Summary!D3 | C3: =Weekly_Summary!E3 | D3: =Weekly_Summary!G3 | E3: =Weekly_Summary!I3 | F3: =Weekly_Summary!J3 | G3: =G2*(1+E3) | H3: =C3/MAX($C$2:C3)-1 | I3: =G3/MAX($G$2:G3)-1 | J3: =AND(A3>=DATEVALUE("2024-01-12"),A3<=DATEVALUE("2026-06-26"))
A4: =Weekly_Summary!B4 | B4: =Weekly_Summary!D4 | C4: =Weekly_Summary!E4 | D4: =Weekly_Summary!G4 | E4: =Weekly_Summary!I4 | F4: =Weekly_Summary!J4 | G4: =G3*(1+E4) | H4: =C4/MAX($C$2:C4)-1 | I4: =G4/MAX($G$2:G4)-1 | J4: =AND(A4>=DATEVALUE("2024-01-12"),A4<=DATEVALUE("2026-06-26"))
A5: =Weekly_Summary!B5 | B5: =Weekly_Summary!D5 | C5: =Weekly_Summary!E5 | D5: =Weekly_Summary!G5 | E5: =Weekly_Summary!I5 | F5: =Weekly_Summary!J5 | G5: =G4*(1+E5) | H5: =C5/MAX($C$2:C5)-1 | I5: =G5/MAX($G$2:G5)-1 | J5: =AND(A5>=DATEVALUE("2024-01-12"),A5<=DATEVALUE("2026-06-26"))
A6: =Weekly_Summary!B6 | B6: =Weekly_Summary!D6 | C6: =Weekly_Summary!E6 | D6: =Weekly_Summary!G6 | E6: =Weekly_Summary!I6 | F6: =Weekly_Summary!J6 | G6: =G5*(1+E6) | H6: =C6/MAX($C$2:C6)-1 | I6: =G6/MAX($G$2:G6)-1 | J6: =AND(A6>=DATEVALUE("2024-01-12"),A6<=DATEVALUE("2026-06-26"))
A7: =Weekly_Summary!B7 | B7: =Weekly_Summary!D7 | C7: =Weekly_Summary!E7 | D7: =Weekly_Summary!G7 | E7: =Weekly_Summary!I7 | F7: =Weekly_Summary!J7 | G7: =G6*(1+E7) | H7: =C7/MAX($C$2:C7)-1 | I7: =G7/MAX($G$2:G7)-1 | J7: =AND(A7>=DATEVALUE("2024-01-12"),A7<=DATEVALUE("2026-06-26"))
A8: =Weekly_Summary!B8 | B8: =Weekly_Summary!D8 | C8: =Weekly_Summary!E8 | D8: =Weekly_Summary!G8 | E8: =Weekly_Summary!I8 | F8: =Weekly_Summary!J8 | G8: =G7*(1+E8) | H8: =C8/MAX($C$2:C8)-1 | I8: =G8/MAX($G$2:G8)-1 | J8: =AND(A8>=DATEVALUE("2024-01-12"),A8<=DATEVALUE("2026-06-26"))
A9: =Weekly_Summary!B9 | B9: =Weekly_Summary!D9 | C9: =Weekly_Summary!E9 | D9: =Weekly_Summary!G9 | E9: =Weekly_Summary!I9 | F9: =Weekly_Summary!J9 | G9: =G8*(1+E9) | H9: =C9/MAX($C$2:C9)-1 | I9: =G9/MAX($G$2:G9)-1 | J9: =AND(A9>=DATEVALUE("2024-01-12"),A9<=DATEVALUE("2026-06-26"))
A10: =Weekly_Summary!B10 | B10: =Weekly_Summary!D10 | C10: =Weekly_Summary!E10 | D10: =Weekly_Summary!G10 | E10: =Weekly_Summary!I10 | F10: =Weekly_Summary!J10 | G10: =G9*(1+E10) | H10: =C10/MAX($C$2:C10)-1 | I10: =G10/MAX($G$2:G10)-1 | J10: =AND(A10>=DATEVALUE("2024-01-12"),A10<=DATEVALUE("2026-06-26"))
A11: =Weekly_Summary!B11 | B11: =Weekly_Summary!D11 | C11: =Weekly_Summary!E11 | D11: =Weekly_Summary!G11 | E11: =Weekly_Summary!I11 | F11: =Weekly_Summary!J11 | G11: =G10*(1+E11) | H11: =C11/MAX($C$2:C11)-1 | I11: =G11/MAX($G$2:G11)-1 | J11: =AND(A11>=DATEVALUE("2024-01-12"),A11<=DATEVALUE("2026-06-26"))
A12: =Weekly_Summary!B12 | B12: =Weekly_Summary!D12 | C12: =Weekly_Summary!E12 | D12: =Weekly_Summary!G12 | E12: =Weekly_Summary!I12 | F12: =Weekly_Summary!J12 | G12: =G11*(1+E12) | H12: =C12/MAX($C$2:C12)-1 | I12: =G12/MAX($G$2:G12)-1 | J12: =AND(A12>=DATEVALUE("2024-01-12"),A12<=DATEVALUE("2026-06-26"))
A13: =Weekly_Summary!B13 | B13: =Weekly_Summary!D13 | C13: =Weekly_Summary!E13 | D13: =Weekly_Summary!G13 | E13: =Weekly_Summary!I13 | F13: =Weekly_Summary!J13 | G13: =G12*(1+E13) | H13: =C13/MAX($C$2:C13)-1 | I13: =G13/MAX($G$2:G13)-1 | J13: =AND(A13>=DATEVALUE("2024-01-12"),A13<=DATEVALUE("2026-06-26"))
A14: =Weekly_Summary!B14 | B14: =Weekly_Summary!D14 | C14: =Weekly_Summary!E14 | D14: =Weekly_Summary!G14 | E14: =Weekly_Summary!I14 | F14: =Weekly_Summary!J14 | G14: =G13*(1+E14) | H14: =C14/MAX($C$2:C14)-1 | I14: =G14/MAX($G$2:G14)-1 | J14: =AND(A14>=DATEVALUE("2024-01-12"),A14<=DATEVALUE("2026-06-26"))
... A183: =Weekly_Summary!B183 | B183: =Weekly_Summary!D183 | C183: =Weekly_Summary!E183 | D183: =Weekly_Summary!G183 | E183: =Weekly_Summary!I183 | F183: =Weekly_Summary!J183 | G183: =G182*(1+E183) | H183: =C183/MAX($C$2:C183)-1 | I183: =G183/MAX($G$2:G183)-1 | J183: =AND(A183>=DATEVALUE("2024-01-12"),A183<=DATEVALUE("2026-06-26"))

Sheet Weekly_Summary
A1: Market | B1: WeekEnding | C1: Benchmark | D1: portfolio_start_value | E1: portfolio_end_value | F1: weekly_pnl | G1: weekly_return | H1: strategy_return | I1: benchmark_return | J1: excess_return | K1: action | L1: in_tickers | M1: out_tickers | N1: selected_count
A2: DJ30 | B2: 2023-01-06 | C2: DIA | D2: =Rebalance_Audit!J32 | E2: =Rebalance_Audit!R32 | F2: =E2-D2 | G2: =IF(D2=0,0,F2/D2) | J2: =G2-I2 | K2: hold | N2: 0
A3: DJ30 | B3: 2023-01-13 | C3: DIA | D3: =Rebalance_Audit!J63 | E3: =Rebalance_Audit!R63 | F3: =E3-D3 | G3: =IF(D3=0,0,F3/D3) | H3: 0 | I3: 0.020102628 | J3: =G3-I3 | K3: hold | N3: 0
A4: DJ30 | B4: 2023-01-20 | C4: DIA | D4: =Rebalance_Audit!J94 | E4: =Rebalance_Audit!R94 | F4: =E4-D4 | G4: =IF(D4=0,0,F4/D4) | H4: 0 | I4: -0.026489999 | J4: =G4-I4 | K4: hold | N4: 0
A5: DJ30 | B5: 2023-01-27 | C5: DIA | D5: =Rebalance_Audit!J125 | E5: =Rebalance_Audit!R125 | F5: =E5-D5 | G5: =IF(D5=0,0,F5/D5) | H5: 0 | I5: 0.017801471 | J5: =G5-I5 | K5: hold | N5: 0
A6: DJ30 | B6: 2023-02-03 | C6: DIA | D6: =Rebalance_Audit!J156 | E6: =Rebalance_Audit!R156 | F6: =E6-D6 | G6: =IF(D6=0,0,F6/D6) | H6: 0 | I6: -0.0018549393 | J6: =G6-I6 | K6: hold | N6: 0
A7: DJ30 | B7: 2023-02-10 | C7: DIA | D7: =Rebalance_Audit!J187 | E7: =Rebalance_Audit!R187 | F7: =E7-D7 | G7: =IF(D7=0,0,F7/D7) | H7: 0 | I7: -0.00073737765 | J7: =G7-I7 | K7: hold | N7: 0
A8: DJ30 | B8: 2023-02-17 | C8: DIA | D8: =Rebalance_Audit!J218 | E8: =Rebalance_Audit!R218 | F8: =E8-D8 | G8: =IF(D8=0,0,F8/D8) | H8: 0 | I8: 0.00033766872 | J8: =G8-I8 | K8: hold | N8: 0
A9: DJ30 | B9: 2023-02-24 | C9: DIA | D9: =Rebalance_Audit!J249 | E9: =Rebalance_Audit!R249 | F9: =E9-D9 | G9: =IF(D9=0,0,F9/D9) | H9: 0 | I9: -0.030062717 | J9: =G9-I9 | K9: hold | N9: 0
A10: DJ30 | B10: 2023-03-03 | C10: DIA | D10: =Rebalance_Audit!J280 | E10: =Rebalance_Audit!R280 | F10: =E10-D10 | G10: =IF(D10=0,0,F10/D10) | H10: 0 | I10: 0.018559828 | J10: =G10-I10 | K10: hold | N10: 0
A11: DJ30 | B11: 2023-03-10 | C11: DIA | D11: =Rebalance_Audit!J311 | E11: =Rebalance_Audit!R311 | F11: =E11-D11 | G11: =IF(D11=0,0,F11/D11) | H11: 0 | I11: -0.043325805 | J11: =G11-I11 | K11: hold | N11: 0
A12: DJ30 | B12: 2023-03-17 | C12: DIA | D12: =Rebalance_Audit!J342 | E12: =Rebalance_Audit!R342 | F12: =E12-D12 | G12: =IF(D12=0,0,F12/D12) | H12: 0 | I12: -0.0011960564 | J12: =G12-I12 | K12: hold | N12: 0
A13: DJ30 | B13: 2023-03-24 | C13: DIA | D13: =Rebalance_Audit!J373 | E13: =Rebalance_Audit!R373 | F13: =E13-D13 | G13: =IF(D13=0,0,F13/D13) | H13: 0 | I13: 0.011993808 | J13: =G13-I13 | K13: hold | N13: 0
A14: DJ30 | B14: 2023-03-31 | C14: DIA | D14: =Rebalance_Audit!J404 | E14: =Rebalance_Audit!R404 | F14: =E14-D14 | G14: =IF(D14=0,0,F14/D14) | H14: 0 | I14: 0.031956004 | J14: =G14-I14 | K14: hold | N14: 0
A15: DJ30 | B15: 2023-04-07 | C15: DIA | D15: =Rebalance_Audit!J435 | E15: =Rebalance_Audit!R435 | F15: =E15-D15 | G15: =IF(D15=0,0,F15/D15) | H15: 0 | I15: 0.0068543459 | J15: =G15-I15 | K15: hold | N15: 0
A16: DJ30 | B16: 2023-04-14 | C16: DIA | D16: =Rebalance_Audit!J466 | E16: =Rebalance_Audit!R466 | F16: =E16-D16 | G16: =IF(D16=0,0,F16/D16) | H16: 0 | I16: 0.011764727 | J16: =G16-I16 | K16: hold | N16: 0
A17: DJ30 | B17: 2023-04-21 | C17: DIA | D17: =Rebalance_Audit!J497 | E17: =Rebalance_Audit!R497 | F17: =E17-D17 | G17: =IF(D17=0,0,F17/D17) | H17: 0 | I17: -0.0016106573 | J17: =G17-I17 | K17: hold | N17: 0
A18: DJ30 | B18: 2023-04-28 | C18: DIA | D18: =Rebalance_Audit!J528 | E18: =Rebalance_Audit!R528 | F18: =E18-D18 | G18: =IF(D18=0,0,F18/D18) | H18: 0 | I18: 0.0086361335 | J18: =G18-I18 | K18: hold | N18: 0
A19: DJ30 | B19: 2023-05-05 | C19: DIA | D19: =Rebalance_Audit!J559 | E19: =Rebalance_Audit!R559 | F19: =E19-D19 | G19: =IF(D19=0,0,F19/D19) | H19: 0 | I19: -0.012609105 | J19: =G19-I19 | K19: hold | N19: 0
A20: DJ30 | B20: 2023-05-12 | C20: DIA | D20: =Rebalance_Audit!J590 | E20: =Rebalance_Audit!R590 | F20: =E20-D20 | G20: =IF(D20=0,0,F20/D20) | H20: 0 | I20: -0.010482701 | J20: =G20-I20 | K20: hold | N20: 0
A21: DJ30 | B21: 2023-05-19 | C21: DIA | D21: =Rebalance_Audit!J621 | E21: =Rebalance_Audit!R621 | F21: =E21-D21 | G21: =IF(D21=0,0,F21/D21) | H21: 0 | I21: 0.005142405 | J21: =G21-I21 | K21: hold | N21: 0
A22: DJ30 | B22: 2023-05-26 | C22: DIA | D22: =Rebalance_Audit!J652 | E22: =Rebalance_Audit!R652 | F22: =E22-D22 | G22: =IF(D22=0,0,F22/D22) | H22: 0 | I22: -0.010024271 | J22: =G22-I22 | K22: hold | N22: 0
A23: DJ30 | B23: 2023-06-02 | C23: DIA | D23: =Rebalance_Audit!J683 | E23: =Rebalance_Audit!R683 | F23: =E23-D23 | G23: =IF(D23=0,0,F23/D23) | H23: 0 | I23: 0.021853463 | J23: =G23-I23 | K23: hold | N23: 0
A24: DJ30 | B24: 2023-06-09 | C24: DIA | D24: =Rebalance_Audit!J714 | E24: =Rebalance_Audit!R714 | F24: =E24-D24 | G24: =IF(D24=0,0,F24/D24) | H24: 0 | I24: 0.0035496151 | J24: =G24-I24 | K24: hold | N24: 0
A25: DJ30 | B25: 2023-06-16 | C25: DIA | D25: =Rebalance_Audit!J745 | E25: =Rebalance_Audit!R745 | F25: =E25-D25 | G25: =IF(D25=0,0,F25/D25) | H25: 0 | I25: 0.013127041 | J25: =G25-I25 | K25: hold | N25: 0
A26: DJ30 | B26: 2023-06-23 | C26: DIA | D26: =Rebalance_Audit!J776 | E26: =Rebalance_Audit!R776 | F26: =E26-D26 | G26: =IF(D26=0,0,F26/D26) | H26: 0 | I26: -0.016883069 | J26: =G26-I26 | K26: hold | N26: 0
A27: DJ30 | B27: 2023-06-30 | C27: DIA | D27: =Rebalance_Audit!J807 | E27: =Rebalance_Audit!R807 | F27: =E27-D27 | G27: =IF(D27=0,0,F27/D27) | H27: 0 | I27: 0.019842621 | J27: =G27-I27 | K27: hold | N27: 0
A28: DJ30 | B28: 2023-07-07 | C28: DIA | D28: =Rebalance_Audit!J838 | E28: =Rebalance_Audit!R838 | F28: =E28-D28 | G28: =IF(D28=0,0,F28/D28) | H28: 0 | I28: -0.018671128 | J28: =G28-I28 | K28: hold | N28: 0
A29: DJ30 | B29: 2023-07-14 | C29: DIA | D29: =Rebalance_Audit!J869 | E29: =Rebalance_Audit!R869 | F29: =E29-D29 | G29: =IF(D29=0,0,F29/D29) | H29: 0 | I29: 0.022938121 | J29: =G29-I29 | K29: hold | N29: 0
A30: DJ30 | B30: 2023-07-21 | C30: DIA | D30: =Rebalance_Audit!J900 | E30: =Rebalance_Audit!R900 | F30: =E30-D30 | G30: =IF(D30=0,0,F30/D30) | H30: 0 | I30: 0.020969381 | J30: =G30-I30 | K30: hold | N30: 0
A31: DJ30 | B31: 2023-07-28 | C31: DIA | D31: =Rebalance_Audit!J931 | E31: =Rebalance_Audit!R931 | F31: =E31-D31 | G31: =IF(D31=0,0,F31/D31) | H31: 0 | I31: 0.0066451963 | J31: =G31-I31 | K31: hold | N31: 0
A32: DJ30 | B32: 2023-08-04 | C32: DIA | D32: =Rebalance_Audit!J962 | E32: =Rebalance_Audit!R962 | F32: =E32-D32 | G32: =IF(D32=0,0,F32/D32) | H32: 0 | I32: -0.010804796 | J32: =G32-I32 | K32: hold | N32: 0
A33: DJ30 | B33: 2023-08-11 | C33: DIA | D33: =Rebalance_Audit!J993 | E33: =Rebalance_Audit!R993 | F33: =E33-D33 | G33: =IF(D33=0,0,F33/D33) | H33: 0 | I33: 0.0067015795 | J33: =G33-I33 | K33: hold | N33: 0
A34: DJ30 | B34: 2023-08-18 | C34: DIA | D34: =Rebalance_Audit!J1024 | E34: =Rebalance_Audit!R1024 | F34: =E34-D34 | G34: =IF(D34=0,0,F34/D34) | H34: 0 | I34: -0.020875357 | J34: =G34-I34 | K34: hold | N34: 0
A35: DJ30 | B35: 2023-08-25 | C35: DIA | D35: =Rebalance_Audit!J1055 | E35: =Rebalance_Audit!R1055 | F35: =E35-D35 | G35: =IF(D35=0,0,F35/D35) | H35: 0 | I35: -0.0046938781 | J35: =G35-I35 | K35: hold | N35: 0
A36: DJ30 | B36: 2023-09-01 | C36: DIA | D36: =Rebalance_Audit!J1086 | E36: =Rebalance_Audit!R1086 | F36: =E36-D36 | G36: =IF(D36=0,0,F36/D36) | H36: 0 | I36: 0.015953283 | J36: =G36-I36 | K36: hold | N36: 0
A37: DJ30 | B37: 2023-09-08 | C37: DIA | D37: =Rebalance_Audit!J1117 | E37: =Rebalance_Audit!R1117 | F37: =E37-D37 | G37: =IF(D37=0,0,F37/D37) | H37: 0 | I37: -0.0070778637 | J37: =G37-I37 | K37: hold | N37: 0
A38: DJ30 | B38: 2023-09-15 | C38: DIA | D38: =Rebalance_Audit!J1148 | E38: =Rebalance_Audit!R1148 | F38: =E38-D38 | G38: =IF(D38=0,0,F38/D38) | H38: 0 | I38: 0.0015741392 | J38: =G38-I38 | K38: hold | N38: 0
A39: DJ30 | B39: 2023-09-22 | C39: DIA | D39: =Rebalance_Audit!J1179 | E39: =Rebalance_Audit!R1179 | F39: =E39-D39 | G39: =IF(D39=0,0,F39/D39) | H39: 0 | I39: -0.018951896 | J39: =G39-I39 | K39: hold | N39: 0
A40: DJ30 | B40: 2023-09-29 | C40: DIA | D40: =Rebalance_Audit!J1210 | E40: =Rebalance_Audit!R1210 | F40: =E40-D40 | G40: =IF(D40=0,0,F40/D40) | H40: 0 | I40: -0.013634611 | J40: =G40-I40 | K40: hold | N40: 0
...

Sheet Rebalance_Audit
A1: Market | B1: WeekEnding | C1: Benchmark | D1: Asset | E1: Company | F1: Sector | G1: last_price | H1: position_before | I1: qty_before | J1: value_before | K1: weight_before | L1: Status | M1: target_weight | N1: value_change | O1: qty_change | P1: position_after | Q1: qty_after | R1: value_after | S1: weight_after | T1: strategy_return | U1: benchmark_return | V1: notes
A2: DJ30 | B2: 2023-01-06 | C2: DIA | D2: AAPL | E2: AAPL | F2: - | G2: 127.45676 | I2: =IF(M2>0,InitialCapital/5/G2,0) | J2: =I2*G2 | K2: =IF($J$32=0,0,J2/$J$32) | L2: REJECTED | M2: 0 | N2: =M2*$J$32-J2 | O2: =IF(G2=0,0,N2/G2) | P2: =IF(M2>0,D2,"") | Q2: =I2+O2 | R2: =Q2*G2 | S2: =IF($R$32=0,0,R2/$R$32) | V2: not in initial selection
A3: DJ30 | B3: 2023-01-06 | C3: DIA | D3: AMGN | E3: AMGN | F3: - | G3: 246.45937 | I3: =IF(M3>0,InitialCapital/5/G3,0) | J3: =I3*G3 | K3: =IF($J$32=0,0,J3/$J$32) | L3: REJECTED | M3: 0 | N3: =M3*$J$32-J3 | O3: =IF(G3=0,0,N3/G3) | P3: =IF(M3>0,D3,"") | Q3: =I3+O3 | R3: =Q3*G3 | S3: =IF($R$32=0,0,R3/$R$32) | V3: not in initial selection
A4: DJ30 | B4: 2023-01-06 | C4: DIA | D4: AMZN | E4: AMZN | F4: - | G4: 86.080002 | I4: =IF(M4>0,InitialCapital/5/G4,0) | J4: =I4*G4 | K4: =IF($J$32=0,0,J4/$J$32) | L4: REJECTED | M4: 0 | N4: =M4*$J$32-J4 | O4: =IF(G4=0,0,N4/G4) | P4: =IF(M4>0,D4,"") | Q4: =I4+O4 | R4: =Q4*G4 | S4: =IF($R$32=0,0,R4/$R$32) | V4: not in initial selection
A5: DJ30 | B5: 2023-01-06 | C5: DIA | D5: AXP | E5: AXP | F5: - | G5: 144.39514 | I5: =IF(M5>0,InitialCapital/5/G5,0) | J5: =I5*G5 | K5: =IF($J$32=0,0,J5/$J$32) | L5: REJECTED | M5: 0 | N5: =M5*$J$32-J5 | O5: =IF(G5=0,0,N5/G5) | P5: =IF(M5>0,D5,"") | Q5: =I5+O5 | R5: =Q5*G5 | S5: =IF($R$32=0,0,R5/$R$32) | V5: not in initial selection
A6: DJ30 | B6: 2023-01-06 | C6: DIA | D6: BA | E6: BA | F6: - | G6: 213 | I6: =IF(M6>0,InitialCapital/5/G6,0) | J6: =I6*G6 | K6: =IF($J$32=0,0,J6/$J$32) | L6: REJECTED | M6: 0 | N6: =M6*$J$32-J6 | O6: =IF(G6=0,0,N6/G6) | P6: =IF(M6>0,D6,"") | Q6: =I6+O6 | R6: =Q6*G6 | S6: =IF($R$32=0,0,R6/$R$32) | V6: not in initial selection
A7: DJ30 | B7: 2023-01-06 | C7: DIA | D7: CAT | E7: CAT | F7: - | G7: 235.4472 | I7: =IF(M7>0,InitialCapital/5/G7,0) | J7: =I7*G7 | K7: =IF($J$32=0,0,J7/$J$32) | L7: REJECTED | M7: 0 | N7: =M7*$J$32-J7 | O7: =IF(G7=0,0,N7/G7) | P7: =IF(M7>0,D7,"") | Q7: =I7+O7 | R7: =Q7*G7 | S7: =IF($R$32=0,0,R7/$R$32) | V7: not in initial selection
A8: DJ30 | B8: 2023-01-06 | C8: DIA | D8: CRM | E8: CRM | F8: - | G8: 138.12045 | I8: =IF(M8>0,InitialCapital/5/G8,0) | J8: =I8*G8 | K8: =IF($J$32=0,0,J8/$J$32) | L8: REJECTED | M8: 0 | N8: =M8*$J$32-J8 | O8: =IF(G8=0,0,N8/G8) | P8: =IF(M8>0,D8,"") | Q8: =I8+O8 | R8: =Q8*G8 | S8: =IF($R$32=0,0,R8/$R$32) | V8: not in initial selection
A9: DJ30 | B9: 2023-01-06 | C9: DIA | D9: CSCO | E9: CSCO | F9: - | G9: 44.140488 | I9: =IF(M9>0,InitialCapital/5/G9,0) | J9: =I9*G9 | K9: =IF($J$32=0,0,J9/$J$32) | L9: REJECTED | M9: 0 | N9: =M9*$J$32-J9 | O9: =IF(G9=0,0,N9/G9) | P9: =IF(M9>0,D9,"") | Q9: =I9+O9 | R9: =Q9*G9 | S9: =IF($R$32=0,0,R9/$R$32) | V9: not in initial selection
A10: DJ30 | B10: 2023-01-06 | C10: DIA | D10: CVX | E10: CVX | F10: - | G10: 152.746 | I10: =IF(M10>0,InitialCapital/5/G10,0) | J10: =I10*G10 | K10: =IF($J$32=0,0,J10/$J$32) | L10: REJECTED | M10: 0 | N10: =M10*$J$32-J10 | O10: =IF(G10=0,0,N10/G10) | P10: =IF(M10>0,D10,"") | Q10: =I10+O10 | R10: =Q10*G10 | S10: =IF($R$32=0,0,R10/$R$32) | V10: not in initial selection
A11: DJ30 | B11: 2023-01-06 | C11: DIA | D11: DIS | E11: DIS | F11: - | G11: 91.759125 | I11: =IF(M11>0,InitialCapital/5/G11,0) | J11: =I11*G11 | K11: =IF($J$32=0,0,J11/$J$32) | L11: REJECTED | M11: 0 | N11: =M11*$J$32-J11 | O11: =IF(G11=0,0,N11/G11) | P11: =IF(M11>0,D11,"") | Q11: =I11+O11 | R11: =Q11*G11 | S11: =IF($R$32=0,0,R11/$R$32) | V11: not in initial selection
A12: DJ30 | B12: 2023-01-06 | C12: DIA | D12: GS | E12: GS | F12: - | G12: 319.72012 | I12: =IF(M12>0,InitialCapital/5/G12,0) | J12: =I12*G12 | K12: =IF($J$32=0,0,J12/$J$32) | L12: REJECTED | M12: 0 | N12: =M12*$J$32-J12 | O12: =IF(G12=0,0,N12/G12) | P12: =IF(M12>0,D12,"") | Q12: =I12+O12 | R12: =Q12*G12 | S12: =IF($R$32=0,0,R12/$R$32) | V12: not in initial selection
A13: DJ30 | B13: 2023-01-06 | C13: DIA | D13: HD | E13: HD | F13: - | G13: 290.08255 | I13: =IF(M13>0,InitialCapital/5/G13,0) | J13: =I13*G13 | K13: =IF($J$32=0,0,J13/$J$32) | L13: REJECTED | M13: 0 | N13: =M13*$J$32-J13 | O13: =IF(G13=0,0,N13/G13) | P13: =IF(M13>0,D13,"") | Q13: =I13+O13 | R13: =Q13*G13 | S13: =IF($R$32=0,0,R13/$R$32) | V13: not in initial selection
... A31: DJ30 | B31: 2023-01-06 | C31: DIA | D31: WMT | E31: WMT | F31: - | G31: 46.983047 | I31: =IF(M31>0,InitialCapital/5/G31,0) | J31: =I31*G31 | K31: =IF($J$32=0,0,J31/$J$32) | L31: REJECTED | M31: 0 | N31: =M31*$J$32-J31 | O31: =IF(G31=0,0,N31/G31) | P31: =IF(M31>0,D31,"") | Q31: =I31+O31 | R31: =Q31*G31 | S31: =IF($R$32=0,0,R31/$R$32) | V31: not in initial selection
A32: DJ30 | B32: 2023-01-06 | C32: DIA | D32: Tot Portfolio | J32: =SUM(J2:J31) | K32: =SUM(K2:K31) | L32: TOTAL | M32: =SUM(M2:M31) | N32: =SUM(N2:N31) | O32: =SUM(O2:O31) | R32: =SUM(R2:R31) | S32: =SUM(S2:S31)
A33: DJ30 | B33: 2023-01-13 | C33: DIA | D33: AAPL | E33: AAPL | F33: - | G33: 132.511 | H33: =P2 | I33: =Q2 | J33: =I33*G33 | K33: =IF($J$63=0,0,J33/$J$63) | L33: REJECTED | M33: 0 | N33: =M33*$J$63-J33 | O33: =IF(G33=0,0,N33/G33) | P33: =IF(M33>0,D33,"") | Q33: =I33+O33 | R33: =Q33*G33 | S33: =IF($R$63=0,0,R33/$R$63) | T33: 0 | U33: 0.020102628 | V33: not selected
A34: DJ30 | B34: 2023-01-13 | C34: DIA | D34: AMGN | E34: AMGN | F34: - | G34: 243.35172 | H34: =P3 | I34: =Q3 | J34: =I34*G34 | K34: =IF($J$63=0,0,J34/$J$63) | L34: REJECTED | M34: 0 | N34: =M34*$J$63-J34 | O34: =IF(G34=0,0,N34/G34) | P34: =IF(M34>0,D34,"") | Q34: =I34+O34 | R34: =Q34*G34 | S34: =IF($R$63=0,0,R34/$R$63) | T34: 0 | U34: 0.020102628 | V34: not selected
A35: DJ30 | B35: 2023-01-13 | C35: DIA | D35: AMZN | E35: AMZN | F35: - | G35: 98.120003 | H35: =P4 | I35: =Q4 | J35: =I35*G35 | K35: =IF($J$63=0,0,J35/$J$63) | L35: REJECTED | M35: 0 | N35: =M35*$J$63-J35 | O35: =IF(G35=0,0,N35/G35) | P35: =IF(M35>0,D35,"") | Q35: =I35+O35 | R35: =Q35*G35 | S35: =IF($R$63=0,0,R35/$R$63) | T35: 0 | U35: 0.020102628 | V35: not selected
A36: DJ30 | B36: 2023-01-13 | C36: DIA | D36: AXP | E36: AXP | F36: - | G36: 149.77017 | H36: =P5 | I36: =Q5 | J36: =I36*G36 | K36: =IF($J$63=0,0,J36/$J$63) | L36: REJECTED | M36: 0 | N36: =M36*$J$63-J36 | O36: =IF(G36=0,0,N36/G36) | P36: =IF(M36>0,D36,"") | Q36: =I36+O36 | R36: =Q36*G36 | S36: =IF($R$63=0,0,R36/$R$63) | T36: 0 | U36: 0.020102628 | V36: not selected
A37: DJ30 | B37: 2023-01-13 | C37: DIA | D37: BA | E37: BA | F37: - | G37: 214.13 | H37: =P6 | I37: =Q6 | J37: =I37*G37 | K37: =IF($J$63=0,0,J37/$J$63) | L37: REJECTED | M37: 0 | N37: =M37*$J$63-J37 | O37: =IF(G37=0,0,N37/G37) | P37: =IF(M37>0,D37,"") | Q37: =I37+O37 | R37: =Q37*G37 | S37: =IF($R$63=0,0,R37/$R$63) | T37: 0 | U37: 0.020102628 | V37: not selected
A38: DJ30 | B38: 2023-01-13 | C38: DIA | D38: CAT | E38: CAT | F38: - | G38: 244.5298 | H38: =P7 | I38: =Q7 | J38: =I38*G38 | K38: =IF($J$63=0,0,J38/$J$63) | L38: REJECTED | M38: 0 | N38: =M38*$J$63-J38 | O38: =IF(G38=0,0,N38/G38) | P38: =IF(M38>0,D38,"") | Q38: =I38+O38 | R38: =Q38*G38 | S38: =IF($R$63=0,0,R38/$R$63) | T38: 0 | U38: 0.020102628 | V38: not selected
A39: DJ30 | B39: 2023-01-13 | C39: DIA | D39: CRM | E39: CRM | F39: - | G39: 146.96739 | H39: =P8 | I39: =Q8 | J39: =I39*G39 | K39: =IF($J$63=0,0,J39/$J$63) | L39: REJECTED | M39: 0 | N39: =M39*$J$63-J39 | O39: =IF(G39=0,0,N39/G39) | P39: =IF(M39>0,D39,"") | Q39: =I39+O39 | R39: =Q39*G39 | S39: =IF($R$63=0,0,R39/$R$63) | T39: 0 | U39: 0.020102628 | V39: not selected
A40: DJ30 | B40: 2023-01-13 | C40: DIA | D40: CSCO | E40: CSCO | F40: - | G40: 44.652054 | H40: =P9 | I40: =Q9 | J40: =I40*G40 | K40: =IF($J$63=0,0,J40/$J$63) | L40: REJECTED | M40: 0 | N40: =M40*$J$63-J40 | O40: =IF(G40=0,0,N40/G40) | P40: =IF(M40>0,D40,"") | Q40: =I40+O40 | R40: =Q40*G40 | S40: =IF($R$63=0,0,R40/$R$63) | T40: 0 | U40: 0.020102628 | V40: not selected
A41: DJ30 | B41: 2023-01-13 | C41: DIA | D41: CVX | E41: CVX | F41: - | G41: 153.61111 | H41: =P10 | I41: =Q10 | J41: =I41*G41 | K41: =IF($J$63=0,0,J41/$J$63) | L41: REJECTED | M41: 0 | N41: =M41*$J$63-J41 | O41: =IF(G41=0,0,N41/G41) | P41: =IF(M41>0,D41,"") | Q41: =I41+O41 | R41: =Q41*G41 | S41: =IF($R$63=0,0,R41/$R$63) | T41: 0 | U41: 0.020102628 | V41: not selected
A42: DJ30 | B42: 2023-01-13 | C42: DIA | D42: DIS | E42: DIS | F42: - | G42: 97.113052 | H42: =P11 | I42: =Q11 | J42: =I42*G42 | K42: =IF($J$63=0,0,J42/$J$63) | L42: REJECTED | M42: 0 | N42: =M42*$J$63-J42 | O42: =IF(G42=0,0,N42/G42) | P42: =IF(M42>0,D42,"") | Q42: =I42+O42 | R42: =Q42*G42 | S42: =IF($R$63=0,0,R42/$R$63) | T42: 0 | U42: 0.020102628 | V42: not selected
A43: DJ30 | B43: 2023-01-13 | C43: DIA | D43: GS | E43: GS | F43: - | G43: 343.52829 | H43: =P12 | I43: =Q12 | J43: =I43*G43 | K43: =IF($J$63=0,0,J43/$J$63) | L43: REJECTED | M43: 0 | N43: =M43*$J$63-J43 | O43: =IF(G43=0,0,N43/G43) | P43: =IF(M43>0,D43,"") | Q43: =I43+O43 | R43: =Q43*G43 | S43: =IF($R$63=0,0,R43/$R$63) | T43: 0 | U43: 0.020102628 | V43: not selected
A44: DJ30 | B44: 2023-01-13 | C44: DIA | D44: HD | E44: HD | F44: - | G44: 302.58008 | H44: =P13 | I44: =Q13 | J44: =I44*G44 | K44: =IF($J$63=0,0,J44/$J$63) | L44: REJECTED | M44: 0 | N44: =M44*$J$63-J44 | O44: =IF(G44=0,0,N44/G44) | P44: =IF(M44>0,D44,"") | Q44: =I44+O44 | R44: =Q44*G44 | S44: =IF($R$63=0,0,R44/$R$63) | T44: 0 | U44: 0.020102628 | V44: not selected
... A62: DJ30 | B62: 2023-01-13 | C62: DIA | D62: WMT | E62: WMT | F62: - | G62: 46.506111 | H62: =P31 | I62: =Q31 | J62: =I62*G62 | K62: =IF($J$63=0,0,J62/$J$63) | L62: REJECTED | M62: 0 | N62: =M62*$J$63-J62 | O62: =IF(G62=0,0,N62/G62) | P62: =IF(M62>0,D62,"") | Q62: =I62+O62 | R62: =Q62*G62 | S62: =IF($R$63=0,0,R62/$R$63) | T62: 0 | U62: 0.020102628 | V62: not selected
A63: DJ30 | B63: 2023-01-13 | C63: DIA | D63: Tot Portfolio | J63: =SUM(J33:J62) | K63: =SUM(K33:K62) | L63: TOTAL | M63: =SUM(M33:M62) | N63: =SUM(N33:N62) | O63: =SUM(O33:O62) | R63: =SUM(R33:R62) | S63: =SUM(S33:S62) | T63: 0 | U63: 0.020102628
A64: DJ30 | B64: 2023-01-20 | C64: DIA | D64: AAPL | E64: AAPL | F64: - | G64: 135.56909 | H64: =P33 | I64: =Q33 | J64: =I64*G64 | K64: =IF($J$94=0,0,J64/$J$94) | L64: REJECTED | M64: 0 | N64: =M64*$J$94-J64 | O64: =IF(G64=0,0,N64/G64) | P64: =IF(M64>0,D64,"") | Q64: =I64+O64 | R64: =Q64*G64 | S64: =IF($R$94=0,0,R64/$R$94) | T64: 0 | U64: -0.026489999 | V64: not selected
A65: DJ30 | B65: 2023-01-20 | C65: DIA | D65: AMGN | E65: AMGN | F65: - | G65: 235.74838 | H65: =P34 | I65: =Q34 | J65: =I65*G65 | K65: =IF($J$94=0,0,J65/$J$94) | L65: REJECTED | M65: 0 | N65: =M65*$J$94-J65 | O65: =IF(G65=0,0,N65/G65) | P65: =IF(M65>0,D65,"") | Q65: =I65+O65 | R65: =Q65*G65 | S65: =IF($R$94=0,0,R65/$R$94) | T65: 0 | U65: -0.026489999 | V65: not selected
A66: DJ30 | B66: 2023-01-20 | C66: DIA | D66: AMZN | E66: AMZN | F66: - | G66: 97.25 | H66: =P35 | I66: =Q35 | J66: =I66*G66 | K66: =IF($J$94=0,0,J66/$J$94) | L66: REJECTED | M66: 0 | N66: =M66*$J$94-J66 | O66: =IF(G66=0,0,N66/G66) | P66: =IF(M66>0,D66,"") | Q66: =I66+O66 | R66: =Q66*G66 | S66: =IF($R$94=0,0,R66/$R$94) | T66: 0 | U66: -0.026489999 | V66: not selected
A67: DJ30 | B67: 2023-01-20 | C67: DIA | D67: AXP | E67: AXP | F67: - | G67: 145.77016 | H67: =P36 | I67: =Q36 | J67: =I67*G67 | K67: =IF($J$94=0,0,J67/$J$94) | L67: REJECTED | M67: 0 | N67: =M67*$J$94-J67 | O67: =IF(G67=0,0,N67/G67) | P67: =IF(M67>0,D67,"") | Q67: =I67+O67 | R67: =Q67*G67 | S67: =IF($R$94=0,0,R67/$R$94) | T67: 0 | U67: -0.026489999 | V67: not selected
A68: DJ30 | B68: 2023-01-20 | C68: DIA | D68: BA | E68: BA | F68: - | G68: 206.75999 | H68: =P37 | I68: =Q37 | J68: =I68*G68 | K68: =IF($J$94=0,0,J68/$J$94) | L68: REJECTED | M68: 0 | N68: =M68*$J$94-J68 | O68: =IF(G68=0,0,N68/G68) | P68: =IF(M68>0,D68,"") | Q68: =I68+O68 | R68: =Q68*G68 | S68: =IF($R$94=0,0,R68/$R$94) | T68: 0 | U68: -0.026489999 | V68: not selected
A69: DJ30 | B69: 2023-01-20 | C69: DIA | D69: CAT | E69: CAT | F69: - | G69: 237.37811 | H69: =P38 | I69: =Q38 | J69: =I69*G69 | K69: =IF($J$94=0,0,J69/$J$94) | L69: REJECTED | M69: 0 | N69: =M69*$J$94-J69 | O69: =IF(G69=0,0,N69/G69) | P69: =IF(M69>0,D69,"") | Q69: =I69+O69 | R69: =Q69*G69 | S69: =IF($R$94=0,0,R69/$R$94) | T69: 0 | U69: -0.026489999 | V69: not selected
A70: DJ30 | B70: 2023-01-20 | C70: DIA | D70: CRM | E70: CRM | F70: - | G70: 148.6778 | H70: =P39 | I70: =Q39 | J70: =I70*G70 | K70: =IF($J$94=0,0,J70/$J$94) | L70: REJECTED | M70: 0 | N70: =M70*$J$94-J70 | O70: =IF(G70=0,0,N70/G70) | P70: =IF(M70>0,D70,"") | Q70: =I70+O70 | R70: =Q70*G70 | S70: =IF($R$94=0,0,R70/$R$94) | T70: 0 | U70: -0.026489999 | V70: not selected
A71: DJ30 | B71: 2023-01-20 | C71: DIA | D71: CSCO | E71: CSCO | F71: - | G71: 42.733696 | H71: =P40 | I71: =Q40 | J71: =I71*G71 | K71: =IF($J$94=0,0,J71/$J$94) | L71: REJECTED | M71: 0 | N71: =M71*$J$94-J71 | O71: =IF(G71=0,0,N71/G71) | P71: =IF(M71>0,D71,"") | Q71: =I71+O71 | R71: =Q71*G71 | S71: =IF($R$94=0,0,R71/$R$94) | T71: 0 | U71: -0.026489999 | V71: not selected
A72: DJ30 | B72: 2023-01-20 | C72: DIA | D72: CVX | E72: CVX | F72: - | G72: 156.50061 | H72: =P41 | I72: =Q41 | J72: =I72*G72 | K72: =IF($J$94=0,0,J72/$J$94) | L72: REJECTED | M72: 0 | N72: =M72*$J$94-J72 | O72: =IF(G72=0,0,N72/G72) | P72: =IF(M72>0,D72,"") | Q72: =I72+O72 | R72: =Q72*G72 | S72: =IF($R$94=0,0,R72/$R$94) | T72: 0 | U72: -0.026489999 | V72: not selected
A73: DJ30 | B73: 2023-01-20 | C73: DIA | D73: DIS | E73: DIS | F73: - | G73: 101.09918 | H73: =P42 | I73: =Q42 | J73: =I73*G73 | K73: =IF($J$94=0,0,J73/$J$94) | L73: REJECTED | M73: 0 | N73: =M73*$J$94-J73 | O73: =IF(G73=0,0,N73/G73) | P73: =IF(M73>0,D73,"") | Q73: =I73+O73 | R73: =Q73*G73 | S73: =IF($R$94=0,0,R73/$R$94) | T73: 0 | U73: -0.026489999 | V73: not selected
A74: DJ30 | B74: 2023-01-20 | C74: DIA | D74: GS | E74: GS | F74: - | G74: 313.98856 | H74: =P43 | I74: =Q43 | J74: =I74*G74 | K74: =IF($J$94=0,0,J74/$J$94) | L74: REJECTED | M74: 0 | N74: =M74*$J$94-J74 | O74: =IF(G74=0,0,N74/G74) | P74: =IF(M74>0,D74,"") | Q74: =I74+O74 | R74: =Q74*G74 | S74: =IF($R$94=0,0,R74/$R$94) | T74: 0 | U74: -0.026489999 | V74: not selected
...

Sheet Holdings_By_Week
A1: Market | B1: WeekEnding | C1: Benchmark | D1: Asset | E1: Company | F1: Sector | G1: last_price | H1: qty_after | I1: value_after | J1: weight_after
A2: DJ30 | B2: 2024-01-05 | C2: DIA | D2: NVDA | E2: NVDA | F2: - | G2: =Rebalance_Audit!G1636 | H2: =Rebalance_Audit!Q1636 | I2: =Rebalance_Audit!R1636 | J2: =Rebalance_Audit!S1636
A3: DJ30 | B3: 2024-01-05 | C3: DIA | D3: AMZN | E3: AMZN | F3: - | G3: =Rebalance_Audit!G1616 | H3: =Rebalance_Audit!Q1616 | I3: =Rebalance_Audit!R1616 | J3: =Rebalance_Audit!S1616
A4: DJ30 | B4: 2024-01-05 | C4: DIA | D4: CRM | E4: CRM | F4: - | G4: =Rebalance_Audit!G1620 | H4: =Rebalance_Audit!Q1620 | I4: =Rebalance_Audit!R1620 | J4: =Rebalance_Audit!S1620
A5: DJ30 | B5: 2024-01-05 | C5: DIA | D5: IBM | E5: IBM | F5: - | G5: =Rebalance_Audit!G1627 | H5: =Rebalance_Audit!Q1627 | I5: =Rebalance_Audit!R1627 | J5: =Rebalance_Audit!S1627
A6: DJ30 | B6: 2024-01-05 | C6: DIA | D6: JPM | E6: JPM | F6: - | G6: =Rebalance_Audit!G1629 | H6: =Rebalance_Audit!Q1629 | I6: =Rebalance_Audit!R1629 | J6: =Rebalance_Audit!S1629
A7: DJ30 | B7: 2024-01-12 | C7: DIA | D7: NVDA | E7: NVDA | F7: - | G7: =Rebalance_Audit!G1667 | H7: =Rebalance_Audit!Q1667 | I7: =Rebalance_Audit!R1667 | J7: =Rebalance_Audit!S1667
A8: DJ30 | B8: 2024-01-12 | C8: DIA | D8: AMZN | E8: AMZN | F8: - | G8: =Rebalance_Audit!G1647 | H8: =Rebalance_Audit!Q1647 | I8: =Rebalance_Audit!R1647 | J8: =Rebalance_Audit!S1647
A9: DJ30 | B9: 2024-01-12 | C9: DIA | D9: CRM | E9: CRM | F9: - | G9: =Rebalance_Audit!G1651 | H9: =Rebalance_Audit!Q1651 | I9: =Rebalance_Audit!R1651 | J9: =Rebalance_Audit!S1651
A10: DJ30 | B10: 2024-01-12 | C10: DIA | D10: AMGN | E10: AMGN | F10: - | G10: =Rebalance_Audit!G1646 | H10: =Rebalance_Audit!Q1646 | I10: =Rebalance_Audit!R1646 | J10: =Rebalance_Audit!S1646
A11: DJ30 | B11: 2024-01-12 | C11: DIA | D11: JPM | E11: JPM | F11: - | G11: =Rebalance_Audit!G1660 | H11: =Rebalance_Audit!Q1660 | I11: =Rebalance_Audit!R1660 | J11: =Rebalance_Audit!S1660
A12: DJ30 | B12: 2024-01-19 | C12: DIA | D12: NVDA | E12: NVDA | F12: - | G12: =Rebalance_Audit!G1698 | H12: =Rebalance_Audit!Q1698 | I12: =Rebalance_Audit!R1698 | J12: =Rebalance_Audit!S1698
A13: DJ30 | B13: 2024-01-19 | C13: DIA | D13: AMZN | E13: AMZN | F13: - | G13: =Rebalance_Audit!G1678 | H13: =Rebalance_Audit!Q1678 | I13: =Rebalance_Audit!R1678 | J13: =Rebalance_Audit!S1678
A14: DJ30 | B14: 2024-01-19 | C14: DIA | D14: CRM | E14: CRM | F14: - | G14: =Rebalance_Audit!G1682 | H14: =Rebalance_Audit!Q1682 | I14: =Rebalance_Audit!R1682 | J14: =Rebalance_Audit!S1682
A15: DJ30 | B15: 2024-01-19 | C15: DIA | D15: AMGN | E15: AMGN | F15: - | G15: =Rebalance_Audit!G1677 | H15: =Rebalance_Audit!Q1677 | I15: =Rebalance_Audit!R1677 | J15: =Rebalance_Audit!S1677
A16: DJ30 | B16: 2024-01-19 | C16: DIA | D16: JPM | E16: JPM | F16: - | G16: =Rebalance_Audit!G1691 | H16: =Rebalance_Audit!Q1691 | I16: =Rebalance_Audit!R1691 | J16: =Rebalance_Audit!S1691
A17: DJ30 | B17: 2024-01-26 | C17: DIA | D17: NVDA | E17: NVDA | F17: - | G17: =Rebalance_Audit!G1729 | H17: =Rebalance_Audit!Q1729 | I17: =Rebalance_Audit!R1729 | J17: =Rebalance_Audit!S1729
A18: DJ30 | B18: 2024-01-26 | C18: DIA | D18: IBM | E18: IBM | F18: - | G18: =Rebalance_Audit!G1720 | H18: =Rebalance_Audit!Q1720 | I18: =Rebalance_Audit!R1720 | J18: =Rebalance_Audit!S1720
A19: DJ30 | B19: 2024-01-26 | C19: DIA | D19: CRM | E19: CRM | F19: - | G19: =Rebalance_Audit!G1713 | H19: =Rebalance_Audit!Q1713 | I19: =Rebalance_Audit!R1713 | J19: =Rebalance_Audit!S1713
A20: DJ30 | B20: 2024-01-26 | C20: DIA | D20: AMGN | E20: AMGN | F20: - | G20: =Rebalance_Audit!G1708 | H20: =Rebalance_Audit!Q1708 | I20: =Rebalance_Audit!R1708 | J20: =Rebalance_Audit!S1708
A21: DJ30 | B21: 2024-01-26 | C21: DIA | D21: JPM | E21: JPM | F21: - | G21: =Rebalance_Audit!G1722 | H21: =Rebalance_Audit!Q1722 | I21: =Rebalance_Audit!R1722 | J21: =Rebalance_Audit!S1722
A22: DJ30 | B22: 2024-02-02 | C22: DIA | D22: NVDA | E22: NVDA | F22: - | G22: =Rebalance_Audit!G1760 | H22: =Rebalance_Audit!Q1760 | I22: =Rebalance_Audit!R1760 | J22: =Rebalance_Audit!S1760
A23: DJ30 | B23: 2024-02-02 | C23: DIA | D23: IBM | E23: IBM | F23: - | G23: =Rebalance_Audit!G1751 | H23: =Rebalance_Audit!Q1751 | I23: =Rebalance_Audit!R1751 | J23: =Rebalance_Audit!S1751
A24: DJ30 | B24: 2024-02-02 | C24: DIA | D24: CRM | E24: CRM | F24: - | G24: =Rebalance_Audit!G1744 | H24: =Rebalance_Audit!Q1744 | I24: =Rebalance_Audit!R1744 | J24: =Rebalance_Audit!S1744
A25: DJ30 | B25: 2024-02-02 | C25: DIA | D25: AMGN | E25: AMGN | F25: - | G25: =Rebalance_Audit!G1739 | H25: =Rebalance_Audit!Q1739 | I25: =Rebalance_Audit!R1739 | J25: =Rebalance_Audit!S1739
A26: DJ30 | B26: 2024-02-02 | C26: DIA | D26: CAT | E26: CAT | F26: - | G26: =Rebalance_Audit!G1743 | H26: =Rebalance_Audit!Q1743 | I26: =Rebalance_Audit!R1743 | J26: =Rebalance_Audit!S1743
A27: DJ30 | B27: 2024-02-09 | C27: DIA | D27: NVDA | E27: NVDA | F27: - | G27: =Rebalance_Audit!G1791 | H27: =Rebalance_Audit!Q1791 | I27: =Rebalance_Audit!R1791 | J27: =Rebalance_Audit!S1791
A28: DJ30 | B28: 2024-02-09 | C28: DIA | D28: IBM | E28: IBM | F28: - | G28: =Rebalance_Audit!G1782 | H28: =Rebalance_Audit!Q1782 | I28: =Rebalance_Audit!R1782 | J28: =Rebalance_Audit!S1782
A29: DJ30 | B29: 2024-02-09 | C29: DIA | D29: CRM | E29: CRM | F29: - | G29: =Rebalance_Audit!G1775 | H29: =Rebalance_Audit!Q1775 | I29: =Rebalance_Audit!R1775 | J29: =Rebalance_Audit!S1775
A30: DJ30 | B30: 2024-02-09 | C30: DIA | D30: AMGN | E30: AMGN | F30: - | G30: =Rebalance_Audit!G1770 | H30: =Rebalance_Audit!Q1770 | I30: =Rebalance_Audit!R1770 | J30: =Rebalance_Audit!S1770
A31: DJ30 | B31: 2024-02-09 | C31: DIA | D31: CAT | E31: CAT | F31: - | G31: =Rebalance_Audit!G1774 | H31: =Rebalance_Audit!Q1774 | I31: =Rebalance_Audit!R1774 | J31: =Rebalance_Audit!S1774
A32: DJ30 | B32: 2024-02-16 | C32: DIA | D32: NVDA | E32: NVDA | F32: - | G32: =Rebalance_Audit!G1822 | H32: =Rebalance_Audit!Q1822 | I32: =Rebalance_Audit!R1822 | J32: =Rebalance_Audit!S1822
A33: DJ30 | B33: 2024-02-16 | C33: DIA | D33: IBM | E33: IBM | F33: - | G33: =Rebalance_Audit!G1813 | H33: =Rebalance_Audit!Q1813 | I33: =Rebalance_Audit!R1813 | J33: =Rebalance_Audit!S1813
A34: DJ30 | B34: 2024-02-16 | C34: DIA | D34: CRM | E34: CRM | F34: - | G34: =Rebalance_Audit!G1806 | H34: =Rebalance_Audit!Q1806 | I34: =Rebalance_Audit!R1806 | J34: =Rebalance_Audit!S1806
A35: DJ30 | B35: 2024-02-16 | C35: DIA | D35: AMGN | E35: AMGN | F35: - | G35: =Rebalance_Audit!G1801 | H35: =Rebalance_Audit!Q1801 | I35: =Rebalance_Audit!R1801 | J35: =Rebalance_Audit!S1801
A36: DJ30 | B36: 2024-02-16 | C36: DIA | D36: CAT | E36: CAT | F36: - | G36: =Rebalance_Audit!G1805 | H36: =Rebalance_Audit!Q1805 | I36: =Rebalance_Audit!R1805 | J36: =Rebalance_Audit!S1805
A37: DJ30 | B37: 2024-02-23 | C37: DIA | D37: NVDA | E37: NVDA | F37: - | G37: =Rebalance_Audit!G1853 | H37: =Rebalance_Audit!Q1853 | I37: =Rebalance_Audit!R1853 | J37: =Rebalance_Audit!S1853
A38: DJ30 | B38: 2024-02-23 | C38: DIA | D38: IBM | E38: IBM | F38: - | G38: =Rebalance_Audit!G1844 | H38: =Rebalance_Audit!Q1844 | I38: =Rebalance_Audit!R1844 | J38: =Rebalance_Audit!S1844
A39: DJ30 | B39: 2024-02-23 | C39: DIA | D39: CRM | E39: CRM | F39: - | G39: =Rebalance_Audit!G1837 | H39: =Rebalance_Audit!Q1837 | I39: =Rebalance_Audit!R1837 | J39: =Rebalance_Audit!S1837
A40: DJ30 | B40: 2024-02-23 | C40: DIA | D40: AMGN | E40: AMGN | F40: - | G40: =Rebalance_Audit!G1832 | H40: =Rebalance_Audit!Q1832 | I40: =Rebalance_Audit!R1832 | J40: =Rebalance_Audit!S1832
...
