Workbook
Name InitialCapital: Config!$B$5

Sheet Config
A1: TradingAlgo Mosaic - DJ30 30 Tickers Rebalance Audit Trial
A3: Market | B3: DJ30
A4: Benchmark | B4: DIA
A5: Initial capital | B5: 100000
A6: Universe size | B6: 30
A7: Price convention | B7: last_price is the Friday closing price used for rebalance calculations.
A8: Execution convention | B8: Signals are calculated after Friday close; implementation is intended at next Monday open.
A9: User action | B9: Change Config!B5 to test a different starting capital.

Sheet Weekly_Summary
A1: Market | B1: WeekEnding | C1: Benchmark | D1: portfolio_start_value | E1: portfolio_end_value | F1: weekly_pnl | G1: weekly_return | H1: benchmark_return | I1: excess_return | J1: action | K1: in_tickers | L1: out_tickers | M1: selected_count
A2: DJ30 | B2: 2026-06-19 | C2: DIA | D2: =Rebalance_Audit!J32 | E2: =Rebalance_Audit!R32 | F2: =E2-D2 | G2: =IF(D2=0,0,F2/D2) | H2: 0.0065 | I2: =G2-H2 | J2: initial | K2: AAPL|CAT|HON|KO|NKE | M2: 5
A3: DJ30 | B3: 2026-06-26 | C3: DIA | D3: =Rebalance_Audit!J63 | E3: =Rebalance_Audit!R63 | F3: =E3-D3 | G3: =IF(D3=0,0,F3/D3) | H3: 0.01 | I3: =G3-H3 | J3: rebalance | K3: AMGN | L3: AAPL | M3: 5
A4: DJ30 | B4: 2026-07-03 | C4: DIA | D4: =Rebalance_Audit!J94 | E4: =Rebalance_Audit!R94 | F4: =E4-D4 | G4: =IF(D4=0,0,F4/D4) | H4: -0.0042 | I4: =G4-H4 | J4: rebalance | K4: MSFT | L4: KO | M4: 5

Sheet Rebalance_Audit
A1: Market | B1: WeekEnding | C1: Benchmark | D1: Asset | E1: Company | F1: Sector | G1: last_price | H1: position_before | I1: qty_before | J1: value_before | K1: weight_before | L1: Status | M1: target_weight | N1: value_change | O1: qty_change | P1: position_after | Q1: qty_after | R1: value_after | S1: weight_after | T1: benchmark_return | U1: notes
A2: DJ30 | B2: 2026-06-19 | C2: DIA | D2: AAPL | E2: AAPL | F2: - | G2: 109.34 | H2: AAPL | I2: =IF(M2>0,InitialCapital/5/G2,0) | J2: =I2*G2 | K2: =IF($J$32=0,0,J2/$J$32) | L2: SELECTED | M2: 0.2 | N2: =M2*$J$32-J2 | O2: =IF(G2=0,0,N2/G2) | P2: =IF(M2>0,D2,"") | Q2: =I2+O2 | R2: =Q2*G2 | S2: =IF($R$32=0,0,R2/$R$32) | T2: 0.0065 | U2: initial model portfolio
A3: DJ30 | B3: 2026-06-19 | C3: DIA | D3: AMGN | E3: AMGN | F3: - | G3: 99.6 | I3: =IF(M3>0,InitialCapital/5/G3,0) | J3: =I3*G3 | K3: =IF($J$32=0,0,J3/$J$32) | L3: WATCHLIST | M3: 0 | N3: =M3*$J$32-J3 | O3: =IF(G3=0,0,N3/G3) | P3: =IF(M3>0,D3,"") | Q3: =I3+O3 | R3: =Q3*G3 | S3: =IF($R$32=0,0,R3/$R$32) | T3: 0.0065 | U3: not in initial selection
A4: DJ30 | B4: 2026-06-19 | C4: DIA | D4: AMZN | E4: AMZN | F4: - | G4: 99.8 | I4: =IF(M4>0,InitialCapital/5/G4,0) | J4: =I4*G4 | K4: =IF($J$32=0,0,J4/$J$32) | L4: WATCHLIST | M4: 0 | N4: =M4*$J$32-J4 | O4: =IF(G4=0,0,N4/G4) | P4: =IF(M4>0,D4,"") | Q4: =I4+O4 | R4: =Q4*G4 | S4: =IF($R$32=0,0,R4/$R$32) | T4: 0.0065 | U4: not in initial selection
A5: DJ30 | B5: 2026-06-19 | C5: DIA | D5: AXP | E5: AXP | F5: - | G5: 100 | I5: =IF(M5>0,InitialCapital/5/G5,0) | J5: =I5*G5 | K5: =IF($J$32=0,0,J5/$J$32) | L5: WATCHLIST | M5: 0 | N5: =M5*$J$32-J5 | O5: =IF(G5=0,0,N5/G5) | P5: =IF(M5>0,D5,"") | Q5: =I5+O5 | R5: =Q5*G5 | S5: =IF($R$32=0,0,R5/$R$32) | T5: 0.0065 | U5: not in initial selection
A6: DJ30 | B6: 2026-06-19 | C6: DIA | D6: BA | E6: BA | F6: - | G6: 100.2 | I6: =IF(M6>0,InitialCapital/5/G6,0) | J6: =I6*G6 | K6: =IF($J$32=0,0,J6/$J$32) | L6: WATCHLIST | M6: 0 | N6: =M6*$J$32-J6 | O6: =IF(G6=0,0,N6/G6) | P6: =IF(M6>0,D6,"") | Q6: =I6+O6 | R6: =Q6*G6 | S6: =IF($R$32=0,0,R6/$R$32) | T6: 0.0065 | U6: not in initial selection
A7: DJ30 | B7: 2026-06-19 | C7: DIA | D7: CAT | E7: CAT | F7: - | G7: 90.36 | H7: CAT | I7: =IF(M7>0,InitialCapital/5/G7,0) | J7: =I7*G7 | K7: =IF($J$32=0,0,J7/$J$32) | L7: SELECTED | M7: 0.2 | N7: =M7*$J$32-J7 | O7: =IF(G7=0,0,N7/G7) | P7: =IF(M7>0,D7,"") | Q7: =I7+O7 | R7: =Q7*G7 | S7: =IF($R$32=0,0,R7/$R$32) | T7: 0.0065 | U7: initial model portfolio
A8: DJ30 | B8: 2026-06-19 | C8: DIA | D8: CRM | E8: CRM | F8: - | G8: 100.6 | I8: =IF(M8>0,InitialCapital/5/G8,0) | J8: =I8*G8 | K8: =IF($J$32=0,0,J8/$J$32) | L8: WATCHLIST | M8: 0 | N8: =M8*$J$32-J8 | O8: =IF(G8=0,0,N8/G8) | P8: =IF(M8>0,D8,"") | Q8: =I8+O8 | R8: =Q8*G8 | S8: =IF($R$32=0,0,R8/$R$32) | T8: 0.0065 | U8: not in initial selection
A9: DJ30 | B9: 2026-06-19 | C9: DIA | D9: CSCO | E9: CSCO | F9: - | G9: 99.4 | I9: =IF(M9>0,InitialCapital/5/G9,0) | J9: =I9*G9 | K9: =IF($J$32=0,0,J9/$J$32) | L9: WATCHLIST | M9: 0 | N9: =M9*$J$32-J9 | O9: =IF(G9=0,0,N9/G9) | P9: =IF(M9>0,D9,"") | Q9: =I9+O9 | R9: =Q9*G9 | S9: =IF($R$32=0,0,R9/$R$32) | T9: 0.0065 | U9: not in initial selection
A10: DJ30 | B10: 2026-06-19 | C10: DIA | D10: CVX | E10: CVX | F10: - | G10: 99.6 | I10: =IF(M10>0,InitialCapital/5/G10,0) | J10: =I10*G10 | K10: =IF($J$32=0,0,J10/$J$32) | L10: WATCHLIST | M10: 0 | N10: =M10*$J$32-J10 | O10: =IF(G10=0,0,N10/G10) | P10: =IF(M10>0,D10,"") | Q10: =I10+O10 | R10: =Q10*G10 | S10: =IF($R$32=0,0,R10/$R$32) | T10: 0.0065 | U10: not in initial selection
A11: DJ30 | B11: 2026-06-19 | C11: DIA | D11: DIS | E11: DIS | F11: - | G11: 99.8 | I11: =IF(M11>0,InitialCapital/5/G11,0) | J11: =I11*G11 | K11: =IF($J$32=0,0,J11/$J$32) | L11: WATCHLIST | M11: 0 | N11: =M11*$J$32-J11 | O11: =IF(G11=0,0,N11/G11) | P11: =IF(M11>0,D11,"") | Q11: =I11+O11 | R11: =Q11*G11 | S11: =IF($R$32=0,0,R11/$R$32) | T11: 0.0065 | U11: not in initial selection
A12: DJ30 | B12: 2026-06-19 | C12: DIA | D12: GS | E12: GS | F12: - | G12: 100 | I12: =IF(M12>0,InitialCapital/5/G12,0) | J12: =I12*G12 | K12: =IF($J$32=0,0,J12/$J$32) | L12: REJECTED | M12: 0 | N12: =M12*$J$32-J12 | O12: =IF(G12=0,0,N12/G12) | P12: =IF(M12>0,D12,"") | Q12: =I12+O12 | R12: =Q12*G12 | S12: =IF($R$32=0,0,R12/$R$32) | T12: 0.0065 | U12: not in initial selection
A13: DJ30 | B13: 2026-06-19 | C13: DIA | D13: HD | E13: HD | F13: - | G13: 100.2 | I13: =IF(M13>0,InitialCapital/5/G13,0) | J13: =I13*G13 | K13: =IF($J$32=0,0,J13/$J$32) | L13: REJECTED | M13: 0 | N13: =M13*$J$32-J13 | O13: =IF(G13=0,0,N13/G13) | P13: =IF(M13>0,D13,"") | Q13: =I13+O13 | R13: =Q13*G13 | S13: =IF($R$32=0,0,R13/$R$32) | T13: 0.0065 | U13: not in initial selection
A14: DJ30 | B14: 2026-06-19 | C14: DIA | D14: HON | E14: HON | F14: - | G14: 102.41 | H14: HON | I14: =IF(M14>0,InitialCapital/5/G14,0) | J14: =I14*G14 | K14: =IF($J$32=0,0,J14/$J$32) | L14: SELECTED | M14: 0.2 | N14: =M14*$J$32-J14 | O14: =IF(G14=0,0,N14/G14) | P14: =IF(M14>0,D14,"") | Q14: =I14+O14 | R14: =Q14*G14 | S14: =IF($R$32=0,0,R14/$R$32) | T14: 0.0065 | U14: initial model portfolio
A15: DJ30 | B15: 2026-06-19 | C15: DIA | D15: IBM | E15: IBM | F15: - | G15: 100.6 | I15: =IF(M15>0,InitialCapital/5/G15,0) | J15: =I15*G15 | K15: =IF($J$32=0,0,J15/$J$32) | L15: REJECTED | M15: 0 | N15: =M15*$J$32-J15 | O15: =IF(G15=0,0,N15/G15) | P15: =IF(M15>0,D15,"") | Q15: =I15+O15 | R15: =Q15*G15 | S15: =IF($R$32=0,0,R15/$R$32) | T15: 0.0065 | U15: not in initial selection
A16: DJ30 | B16: 2026-06-19 | C16: DIA | D16: JNJ | E16: JNJ | F16: - | G16: 99.4 | I16: =IF(M16>0,InitialCapital/5/G16,0) | J16: =I16*G16 | K16: =IF($J$32=0,0,J16/$J$32) | L16: REJECTED | M16: 0 | N16: =M16*$J$32-J16 | O16: =IF(G16=0,0,N16/G16) | P16: =IF(M16>0,D16,"") | Q16: =I16+O16 | R16: =Q16*G16 | S16: =IF($R$32=0,0,R16/$R$32) | T16: 0.0065 | U16: not in initial selection
A17: DJ30 | B17: 2026-06-19 | C17: DIA | D17: JPM | E17: JPM | F17: - | G17: 99.6 | I17: =IF(M17>0,InitialCapital/5/G17,0) | J17: =I17*G17 | K17: =IF($J$32=0,0,J17/$J$32) | L17: REJECTED | M17: 0 | N17: =M17*$J$32-J17 | O17: =IF(G17=0,0,N17/G17) | P17: =IF(M17>0,D17,"") | Q17: =I17+O17 | R17: =Q17*G17 | S17: =IF($R$32=0,0,R17/$R$32) | T17: 0.0065 | U17: not in initial selection
A18: DJ30 | B18: 2026-06-19 | C18: DIA | D18: KO | E18: KO | F18: - | G18: 79.84 | H18: KO | I18: =IF(M18>0,InitialCapital/5/G18,0) | J18: =I18*G18 | K18: =IF($J$32=0,0,J18/$J$32) | L18: SELECTED | M18: 0.2 | N18: =M18*$J$32-J18 | O18: =IF(G18=0,0,N18/G18) | P18: =IF(M18>0,D18,"") | Q18: =I18+O18 | R18: =Q18*G18 | S18: =IF($R$32=0,0,R18/$R$32) | T18: 0.0065 | U18: initial model portfolio
A19: DJ30 | B19: 2026-06-19 | C19: DIA | D19: MCD | E19: MCD | F19: - | G19: 100 | I19: =IF(M19>0,InitialCapital/5/G19,0) | J19: =I19*G19 | K19: =IF($J$32=0,0,J19/$J$32) | L19: REJECTED | M19: 0 | N19: =M19*$J$32-J19 | O19: =IF(G19=0,0,N19/G19) | P19: =IF(M19>0,D19,"") | Q19: =I19+O19 | R19: =Q19*G19 | S19: =IF($R$32=0,0,R19/$R$32) | T19: 0.0065 | U19: not in initial selection
A20: DJ30 | B20: 2026-06-19 | C20: DIA | D20: MMM | E20: MMM | F20: - | G20: 100.2 | I20: =IF(M20>0,InitialCapital/5/G20,0) | J20: =I20*G20 | K20: =IF($J$32=0,0,J20/$J$32) | L20: REJECTED | M20: 0 | N20: =M20*$J$32-J20 | O20: =IF(G20=0,0,N20/G20) | P20: =IF(M20>0,D20,"") | Q20: =I20+O20 | R20: =Q20*G20 | S20: =IF($R$32=0,0,R20/$R$32) | T20: 0.0065 | U20: not in initial selection
A21: DJ30 | B21: 2026-06-19 | C21: DIA | D21: MRK | E21: MRK | F21: - | G21: 100.4 | I21: =IF(M21>0,InitialCapital/5/G21,0) | J21: =I21*G21 | K21: =IF($J$32=0,0,J21/$J$32) | L21: REJECTED | M21: 0 | N21: =M21*$J$32-J21 | O21: =IF(G21=0,0,N21/G21) | P21: =IF(M21>0,D21,"") | Q21: =I21+O21 | R21: =Q21*G21 | S21: =IF($R$32=0,0,R21/$R$32) | T21: 0.0065 | U21: not in initial selection
A22: DJ30 | B22: 2026-06-19 | C22: DIA | D22: MSFT | E22: MSFT | F22: - | G22: 100.6 | I22: =IF(M22>0,InitialCapital/5/G22,0) | J22: =I22*G22 | K22: =IF($J$32=0,0,J22/$J$32) | L22: REJECTED | M22: 0 | N22: =M22*$J$32-J22 | O22: =IF(G22=0,0,N22/G22) | P22: =IF(M22>0,D22,"") | Q22: =I22+O22 | R22: =Q22*G22 | S22: =IF($R$32=0,0,R22/$R$32) | T22: 0.0065 | U22: not in initial selection
A23: DJ30 | B23: 2026-06-19 | C23: DIA | D23: NKE | E23: NKE | F23: - | G23: 99.4 | H23: NKE | I23: =IF(M23>0,InitialCapital/5/G23,0) | J23: =I23*G23 | K23: =IF($J$32=0,0,J23/$J$32) | L23: SELECTED | M23: 0.2 | N23: =M23*$J$32-J23 | O23: =IF(G23=0,0,N23/G23) | P23: =IF(M23>0,D23,"") | Q23: =I23+O23 | R23: =Q23*G23 | S23: =IF($R$32=0,0,R23/$R$32) | T23: 0.0065 | U23: initial model portfolio
A24: DJ30 | B24: 2026-06-19 | C24: DIA | D24: NVDA | E24: NVDA | F24: - | G24: 99.6 | I24: =IF(M24>0,InitialCapital/5/G24,0) | J24: =I24*G24 | K24: =IF($J$32=0,0,J24/$J$32) | L24: REJECTED | M24: 0 | N24: =M24*$J$32-J24 | O24: =IF(G24=0,0,N24/G24) | P24: =IF(M24>0,D24,"") | Q24: =I24+O24 | R24: =Q24*G24 | S24: =IF($R$32=0,0,R24/$R$32) | T24: 0.0065 | U24: not in initial selection
A25: DJ30 | B25: 2026-06-19 | C25: DIA | D25: PG | E25: PG | F25: - | G25: 99.8 | I25: =IF(M25>0,InitialCapital/5/G25,0) | J25: =I25*G25 | K25: =IF($J$32=0,0,J25/$J$32) | L25: REJECTED | M25: 0 | N25: =M25*$J$32-J25 | O25: =IF(G25=0,0,N25/G25) | P25: =IF(M25>0,D25,"") | Q25: =I25+O25 | R25: =Q25*G25 | S25: =IF($R$32=0,0,R25/$R$32) | T25: 0.0065 | U25: not in initial selection
A26: DJ30 | B26: 2026-06-19 | C26: DIA | D26: SHW | E26: SHW | F26: - | G26: 100 | I26: =IF(M26>0,InitialCapital/5/G26,0) | J26: =I26*G26 | K26: =IF($J$32=0,0,J26/$J$32) | L26: REJECTED | M26: 0 | N26: =M26*$J$32-J26 | O26: =IF(G26=0,0,N26/G26) | P26: =IF(M26>0,D26,"") | Q26: =I26+O26 | R26: =Q26*G26 | S26: =IF($R$32=0,0,R26/$R$32) | T26: 0.0065 | U26: not in initial selection
A27: DJ30 | B27: 2026-06-19 | C27: DIA | D27: TRV | E27: TRV | F27: - | G27: 100.2 | I27: =IF(M27>0,InitialCapital/5/G27,0) | J27: =I27*G27 | K27: =IF($J$32=0,0,J27/$J$32) | L27: REJECTED | M27: 0 | N27: =M27*$J$32-J27 | O27: =IF(G27=0,0,N27/G27) | P27: =IF(M27>0,D27,"") | Q27: =I27+O27 | R27: =Q27*G27 | S27: =IF($R$32=0,0,R27/$R$32) | T27: 0.0065 | U27: not in initial selection
A28: DJ30 | B28: 2026-06-19 | C28: DIA | D28: UNH | E28: UNH | F28: - | G28: 100.4 | I28: =IF(M28>0,InitialCapital/5/G28,0) | J28: =I28*G28 | K28: =IF($J$32=0,0,J28/$J$32) | L28: REJECTED | M28: 0 | N28: =M28*$J$32-J28 | O28: =IF(G28=0,0,N28/G28) | P28: =IF(M28>0,D28,"") | Q28: =I28+O28 | R28: =Q28*G28 | S28: =IF($R$32=0,0,R28/$R$32) | T28: 0.0065 | U28: not in initial selection
A29: DJ30 | B29: 2026-06-19 | C29: DIA | D29: V | E29: V | F29: - | G29: 100.6 | I29: =IF(M29>0,InitialCapital/5/G29,0) | J29: =I29*G29 | K29: =IF($J$32=0,0,J29/$J$32) | L29: REJECTED | M29: 0 | N29: =M29*$J$32-J29 | O29: =IF(G29=0,0,N29/G29) | P29: =IF(M29>0,D29,"") | Q29: =I29+O29 | R29: =Q29*G29 | S29: =IF($R$32=0,0,R29/$R$32) | T29: 0.0065 | U29: not in initial selection
A30: DJ30 | B30: 2026-06-19 | C30: DIA | D30: VZ | E30: VZ | F30: - | G30: 99.4 | I30: =IF(M30>0,InitialCapital/5/G30,0) | J30: =I30*G30 | K30: =IF($J$32=0,0,J30/$J$32) | L30: REJECTED | M30: 0 | N30: =M30*$J$32-J30 | O30: =IF(G30=0,0,N30/G30) | P30: =IF(M30>0,D30,"") | Q30: =I30+O30 | R30: =Q30*G30 | S30: =IF($R$32=0,0,R30/$R$32) | T30: 0.0065 | U30: not in initial selection
A31: DJ30 | B31: 2026-06-19 | C31: DIA | D31: WMT | E31: WMT | F31: - | G31: 99.6 | I31: =IF(M31>0,InitialCapital/5/G31,0) | J31: =I31*G31 | K31: =IF($J$32=0,0,J31/$J$32) | L31: REJECTED | M31: 0 | N31: =M31*$J$32-J31 | O31: =IF(G31=0,0,N31/G31) | P31: =IF(M31>0,D31,"") | Q31: =I31+O31 | R31: =Q31*G31 | S31: =IF($R$32=0,0,R31/$R$32) | T31: 0.0065 | U31: not in initial selection
A32: DJ30 | B32: 2026-06-19 | C32: DIA | D32: Tot Portfolio | J32: =SUM(J2:J31) | K32: =SUM(K2:K31) | L32: TOTAL | M32: =SUM(M2:M31) | N32: =SUM(N2:N31) | O32: =SUM(O2:O31) | R32: =SUM(R2:R31) | S32: =SUM(S2:S31) | T32: 0.0065
A33: DJ30 | B33: 2026-06-26 | C33: DIA | D33: AAPL | E33: AAPL | F33: - | G33: 110.44 | H33: =P2 | I33: =Q2 | J33: =I33*G33 | K33: =IF($J$63=0,0,J33/$J$63) | L33: REJECTED | M33: 0 | N33: =M33*$J$63-J33 | O33: =IF(G33=0,0,N33/G33) | P33: =IF(M33>0,D33,"") | Q33: =I33+O33 | R33: =Q33*G33 | S33: =IF($R$63=0,0,R33/$R$63) | T33: 0.01 | U33: removed from weekly selection
A34: DJ30 | B34: 2026-06-26 | C34: DIA | D34: AMGN | E34: AMGN | F34: - | G34: 100.6 | H34: =P3 | I34: =Q3 | J34: =I34*G34 | K34: =IF($J$63=0,0,J34/$J$63) | L34: SELECTED | M34: 0.2 | N34: =M34*$J$63-J34 | O34: =IF(G34=0,0,N34/G34) | P34: =IF(M34>0,D34,"") | Q34: =I34+O34 | R34: =Q34*G34 | S34: =IF($R$63=0,0,R34/$R$63) | T34: 0.01 | U34: entered weekly selection
A35: DJ30 | B35: 2026-06-26 | C35: DIA | D35: AMZN | E35: AMZN | F35: - | G35: 100.8 | H35: =P4 | I35: =Q4 | J35: =I35*G35 | K35: =IF($J$63=0,0,J35/$J$63) | L35: WATCHLIST | M35: 0 | N35: =M35*$J$63-J35 | O35: =IF(G35=0,0,N35/G35) | P35: =IF(M35>0,D35,"") | Q35: =I35+O35 | R35: =Q35*G35 | S35: =IF($R$63=0,0,R35/$R$63) | T35: 0.01 | U35: not selected
A36: DJ30 | B36: 2026-06-26 | C36: DIA | D36: AXP | E36: AXP | F36: - | G36: 101 | H36: =P5 | I36: =Q5 | J36: =I36*G36 | K36: =IF($J$63=0,0,J36/$J$63) | L36: WATCHLIST | M36: 0 | N36: =M36*$J$63-J36 | O36: =IF(G36=0,0,N36/G36) | P36: =IF(M36>0,D36,"") | Q36: =I36+O36 | R36: =Q36*G36 | S36: =IF($R$63=0,0,R36/$R$63) | T36: 0.01 | U36: not selected
A37: DJ30 | B37: 2026-06-26 | C37: DIA | D37: BA | E37: BA | F37: - | G37: 101.2 | H37: =P6 | I37: =Q6 | J37: =I37*G37 | K37: =IF($J$63=0,0,J37/$J$63) | L37: WATCHLIST | M37: 0 | N37: =M37*$J$63-J37 | O37: =IF(G37=0,0,N37/G37) | P37: =IF(M37>0,D37,"") | Q37: =I37+O37 | R37: =Q37*G37 | S37: =IF($R$63=0,0,R37/$R$63) | T37: 0.01 | U37: not selected
A38: DJ30 | B38: 2026-06-26 | C38: DIA | D38: CAT | E38: CAT | F38: - | G38: 91.26 | H38: =P7 | I38: =Q7 | J38: =I38*G38 | K38: =IF($J$63=0,0,J38/$J$63) | L38: SELECTED | M38: 0.2 | N38: =M38*$J$63-J38 | O38: =IF(G38=0,0,N38/G38) | P38: =IF(M38>0,D38,"") | Q38: =I38+O38 | R38: =Q38*G38 | S38: =IF($R$63=0,0,R38/$R$63) | T38: 0.01 | U38: remained in weekly selection
A39: DJ30 | B39: 2026-06-26 | C39: DIA | D39: CRM | E39: CRM | F39: - | G39: 101.6 | H39: =P8 | I39: =Q8 | J39: =I39*G39 | K39: =IF($J$63=0,0,J39/$J$63) | L39: WATCHLIST | M39: 0 | N39: =M39*$J$63-J39 | O39: =IF(G39=0,0,N39/G39) | P39: =IF(M39>0,D39,"") | Q39: =I39+O39 | R39: =Q39*G39 | S39: =IF($R$63=0,0,R39/$R$63) | T39: 0.01 | U39: not selected
A40: DJ30 | B40: 2026-06-26 | C40: DIA | D40: CSCO | E40: CSCO | F40: - | G40: 100.4 | H40: =P9 | I40: =Q9 | J40: =I40*G40 | K40: =IF($J$63=0,0,J40/$J$63) | L40: WATCHLIST | M40: 0 | N40: =M40*$J$63-J40 | O40: =IF(G40=0,0,N40/G40) | P40: =IF(M40>0,D40,"") | Q40: =I40+O40 | R40: =Q40*G40 | S40: =IF($R$63=0,0,R40/$R$63) | T40: 0.01 | U40: not selected
...

Sheet Holdings_By_Week
A1: Market | B1: WeekEnding | C1: Benchmark | D1: Asset | E1: Company | F1: Sector | G1: last_price | H1: qty_after | I1: value_after | J1: weight_after
A2: DJ30 | B2: 2026-06-19 | C2: DIA | D2: AAPL | E2: AAPL | F2: - | G2: =Rebalance_Audit!G2 | H2: =Rebalance_Audit!Q2 | I2: =Rebalance_Audit!R2 | J2: =Rebalance_Audit!S2
A3: DJ30 | B3: 2026-06-19 | C3: DIA | D3: CAT | E3: CAT | F3: - | G3: =Rebalance_Audit!G7 | H3: =Rebalance_Audit!Q7 | I3: =Rebalance_Audit!R7 | J3: =Rebalance_Audit!S7
A4: DJ30 | B4: 2026-06-19 | C4: DIA | D4: HON | E4: HON | F4: - | G4: =Rebalance_Audit!G14 | H4: =Rebalance_Audit!Q14 | I4: =Rebalance_Audit!R14 | J4: =Rebalance_Audit!S14
A5: DJ30 | B5: 2026-06-19 | C5: DIA | D5: KO | E5: KO | F5: - | G5: =Rebalance_Audit!G18 | H5: =Rebalance_Audit!Q18 | I5: =Rebalance_Audit!R18 | J5: =Rebalance_Audit!S18
A6: DJ30 | B6: 2026-06-19 | C6: DIA | D6: NKE | E6: NKE | F6: - | G6: =Rebalance_Audit!G23 | H6: =Rebalance_Audit!Q23 | I6: =Rebalance_Audit!R23 | J6: =Rebalance_Audit!S23
A7: DJ30 | B7: 2026-06-26 | C7: DIA | D7: AMGN | E7: AMGN | F7: - | G7: =Rebalance_Audit!G34 | H7: =Rebalance_Audit!Q34 | I7: =Rebalance_Audit!R34 | J7: =Rebalance_Audit!S34
A8: DJ30 | B8: 2026-06-26 | C8: DIA | D8: CAT | E8: CAT | F8: - | G8: =Rebalance_Audit!G38 | H8: =Rebalance_Audit!Q38 | I8: =Rebalance_Audit!R38 | J8: =Rebalance_Audit!S38
A9: DJ30 | B9: 2026-06-26 | C9: DIA | D9: HON | E9: HON | F9: - | G9: =Rebalance_Audit!G45 | H9: =Rebalance_Audit!Q45 | I9: =Rebalance_Audit!R45 | J9: =Rebalance_Audit!S45
A10: DJ30 | B10: 2026-06-26 | C10: DIA | D10: KO | E10: KO | F10: - | G10: =Rebalance_Audit!G49 | H10: =Rebalance_Audit!Q49 | I10: =Rebalance_Audit!R49 | J10: =Rebalance_Audit!S49
A11: DJ30 | B11: 2026-06-26 | C11: DIA | D11: NKE | E11: NKE | F11: - | G11: =Rebalance_Audit!G54 | H11: =Rebalance_Audit!Q54 | I11: =Rebalance_Audit!R54 | J11: =Rebalance_Audit!S54
A12: DJ30 | B12: 2026-07-03 | C12: DIA | D12: AMGN | E12: AMGN | F12: - | G12: =Rebalance_Audit!G65 | H12: =Rebalance_Audit!Q65 | I12: =Rebalance_Audit!R65 | J12: =Rebalance_Audit!S65
A13: DJ30 | B13: 2026-07-03 | C13: DIA | D13: CAT | E13: CAT | F13: - | G13: =Rebalance_Audit!G69 | H13: =Rebalance_Audit!Q69 | I13: =Rebalance_Audit!R69 | J13: =Rebalance_Audit!S69
A14: DJ30 | B14: 2026-07-03 | C14: DIA | D14: HON | E14: HON | F14: - | G14: =Rebalance_Audit!G76 | H14: =Rebalance_Audit!Q76 | I14: =Rebalance_Audit!R76 | J14: =Rebalance_Audit!S76
A15: DJ30 | B15: 2026-07-03 | C15: DIA | D15: MSFT | E15: MSFT | F15: - | G15: =Rebalance_Audit!G84 | H15: =Rebalance_Audit!Q84 | I15: =Rebalance_Audit!R84 | J15: =Rebalance_Audit!S84
A16: DJ30 | B16: 2026-07-03 | C16: DIA | D16: NKE | E16: NKE | F16: - | G16: =Rebalance_Audit!G85 | H16: =Rebalance_Audit!Q85 | I16: =Rebalance_Audit!R85 | J16: =Rebalance_Audit!S85
